Workbook
Name Bokføringsareale: Regnskap!$E$6:$SJ$12,Regnskap!$E$14:$SJ$17,Regnskap!$E$20:$SJ$27,Regnskap!$E$29:$SJ$61
Name Regnskap: Regnskap!$B$6:$D$61

Sheet Oversikt
B2: [i]
C3: RESULTATOPPSTILLING | F3: BALANSEOPPSTILLING
C8: Høst 2025 | F8: =C8 -> Høst 2025
C10: Inntekter | F10: Eiendeler
C11: =Regnskap!B20 -> 3000 Salgsinntekter | D11: =-VLOOKUP(C11,Regnskap,3,FALSE) -> 3599.15 | F11: =Regnskap!B6 -> 1300 Lån til eksterne | G11: =VLOOKUP(F11,Regnskap,3,FALSE) -> 0
C12: =Regnskap!B21 -> 3100 Medlemskontingent | D12: =-VLOOKUP(C12,Regnskap,3,FALSE) -> 3350 | F12: =Regnskap!B7 -> 1400 Varelager | G12: =VLOOKUP(F12,Regnskap,3,FALSE) -> 0
C13: =Regnskap!B22 -> 3200 Billettinntekter | D13: =-VLOOKUP(C13,Regnskap,3,FALSE) -> 3050 | F13: =Regnskap!B8 -> 1500 Fordringer | G13: =VLOOKUP(F13,Regnskap,3,FALSE) -> 0
C14: =Regnskap!B23 -> 3400 Støtte fra Oslostøtte | D14: =-VLOOKUP(C14,Regnskap,3,FALSE) -> 88686.09 | F14: =Regnskap!B9 -> 1550 Interne fordringer | G14: =VLOOKUP(F14,Regnskap,3,FALSE) -> 0
C15: =Regnskap!B24 -> 3410 Støtte fra Fri Fond | D15: =-VLOOKUP(C15,Regnskap,3,FALSE) -> 60209.43 | F15: =Regnskap!B10 -> 1900 Kontanter | G15: =VLOOKUP(F15,Regnskap,3,FALSE) -> 0
C16: =Regnskap!B25 -> 3420 Støtte fra annen støtteordning | D16: =-VLOOKUP(C16,Regnskap,3,FALSE) -> 40130.74 | F16: =Regnskap!B11 -> 1910 Brukskonto | G16: =VLOOKUP(F16,Regnskap,3,FALSE) -> 120240.12
C17: =Regnskap!B26 -> 3900 Annen inntekt | D17: =-VLOOKUP(C17,Regnskap,3,FALSE) -> 2677.62 | F17: =Regnskap!B12 -> 1920 Sparekonto | G17: =VLOOKUP(F17,Regnskap,3,FALSE) -> 0
C18: =Regnskap!B27 -> 8050 Renteinntekter | D18: =-VLOOKUP(C18,Regnskap,3,FALSE) -> 0 | F18: Sum Eiendeler | G18: =SUM(G11:G17) -> 120240.12
C19: Sum inntekter | D19: =SUM(D11:D18) -> 201703.03
F20: Egenkapital og gjeld
C21: Kostnader | F21: =Regnskap!B14 -> 2050 Egenkapital | G21: =VLOOKUP(F21,Regnskap,3,FALSE) -> 83181.49
C22: =Regnskap!B29 -> 4000 Varekjøp til videresalg | D22: =VLOOKUP(C22,Regnskap,3,FALSE) -> 4938.3 | F22: =Regnskap!B15 -> 2400 Leverandørgjeld | G22: =VLOOKUP(F22,Regnskap,3,FALSE) -> 0
C23: =Regnskap!B30 -> 4300 Forbruk varelager | D23: =VLOOKUP(C23,Regnskap,3,FALSE) -> 0 | F23: =Regnskap!B16 -> 2910 Gjeld til interne (utlegg) | G23: =VLOOKUP(F23,Regnskap,3,FALSE) -> 0
C24: =Regnskap!B31 -> 4390 Beholdningsendring varer | D24: =VLOOKUP(C24,Regnskap,3,FALSE) -> 0 | F24: =Regnskap!B17 -> 2950 Annen gjeld | G24: =VLOOKUP(F24,Regnskap,3,FALSE) -> 0
C25: =Regnskap!B32 -> 5000 Skattefritt honorar, interne | D25: =VLOOKUP(C25,Regnskap,3,FALSE) -> 0 | F25: Sum EK og gjeld | G25: =SUM(G21:G24) -> 83181.49
C26: =Regnskap!B33 -> 5050 Skattefritt honorar, eksterne | D26: =VLOOKUP(C26,Regnskap,3,FALSE) -> 0
C27: =Regnskap!B34 -> 5700 Støtte til andre foreninger | D27: =VLOOKUP(C27,Regnskap,3,FALSE) -> 0
C28: =Regnskap!B35 -> 5900 Gaver ansatte | D28: =VLOOKUP(C28,Regnskap,3,FALSE) -> 0
C29: =Regnskap!B36 -> 5910 Mat og drikke til frivillige | D29: =VLOOKUP(C29,Regnskap,3,FALSE) -> 638
C30: =Regnskap!B37 -> 5920 Mat og drikke til styret | D30: =VLOOKUP(C30,Regnskap,3,FALSE) -> 2989
C31: =Regnskap!B38 -> 6300 Leie av lokaler | D31: =VLOOKUP(C31,Regnskap,3,FALSE) -> 0
C32: =Regnskap!B39 -> 6450 Inventar | D32: =VLOOKUP(C32,Regnskap,3,FALSE) -> 12656
C33: =Regnskap!B40 -> 6550 Driftsmaterialer | D33: =VLOOKUP(C33,Regnskap,3,FALSE) -> 0 | H33: [i]
C34: =Regnskap!B41 -> 6551 Datautstyr | D34: =VLOOKUP(C34,Regnskap,3,FALSE) -> 8331.94
C35: =Regnskap!B42 -> 6552 Programvarer | D35: =VLOOKUP(C35,Regnskap,3,FALSE) -> 1204
C36: =Regnskap!B43 -> 6560 Rekvisita | D36: =VLOOKUP(C36,Regnskap,3,FALSE) -> 0
C37: =Regnskap!B44 -> 6590 Annen driftskostnad | D37: =VLOOKUP(C37,Regnskap,3,FALSE) -> 10238
C38: =Regnskap!B45 -> 6720 Økonomiske og juridiske tjenester | D38: =VLOOKUP(C38,Regnskap,3,FALSE) -> 4520.44
C39: =Regnskap!B46 -> 6750 Arrangementkostnader | D39: =VLOOKUP(C39,Regnskap,3,FALSE) -> 26145.42
C40: =Regnskap!B47 -> 6755 Artist/underholdningshonorar | D40: =VLOOKUP(C40,Regnskap,3,FALSE) -> 0
C41: =Regnskap!B48 -> 6790 Andre fremmedtjenester | D41: =VLOOKUP(C41,Regnskap,3,FALSE) -> 8762.11
C42: =Regnskap!B49 -> 6800 Kontorrekvisita | D42: =VLOOKUP(C42,Regnskap,3,FALSE) -> 486.7
C43: =Regnskap!B50 -> 6815 Internett | D43: =VLOOKUP(C43,Regnskap,3,FALSE) -> 0
C44: =Regnskap!B51 -> 6890 Annen kontorkostnad | D44: =VLOOKUP(C44,Regnskap,3,FALSE) -> 0
C45: =Regnskap!B52 -> 6900 Telefon | D45: =VLOOKUP(C45,Regnskap,3,FALSE) -> 0
... C53: =Regnskap!B60 -> 8150 Rentekostnader | D53: =VLOOKUP(C53,Regnskap,3,FALSE) -> 0
...

Sheet Regnskap
A1: KONTO ØKES MED | B1: BILAGSNUMMER  | E1: #1 | F1: #2 | G1: #3 | H1: #4 | I1: #5 | J1: #6 | K1: #7 | L1: #8 | M1: #9 | N1: #10 | O1: #11 | P1: #12 | Q1: #13 | R1: #14 | S1: #15 | T1: #16 | U1: #17 | V1: #18 | W1: #19 | X1: #20 | Y1: #21 | Z1: #22 | AA1: #23 | AB1: #24 | AC1: #25 | AD1: #26 | AE1: #27 | AF1: #28 | AG1: #29 | AH1: #30 | AI1: #31 | AJ1: #32 | AK1: #33 | AL1: #34 | AM1: #35 | AN1: #36 | AO1: #37 | AP1: #38 | AQ1: #39 | AR1: #40 | AS1: #41 | AT1: #42 | AU1: #43 | AV1: #44 | AW1: #45 | AX1: #46 | AY1: #47 | AZ1: #48 | BA1: #49 | BB1: #50 | BC1: #51 | BD1: #52 | BE1: #53 | BF1: #54 | BG1: #55 | BH1: #56 | BI1: #57 | BJ1: #58 | BK1: #59 | BL1: #60 | BM1: #61 | BN1: #62 | BO1: #63 | BP1: #64 | BQ1: #65 | BR1: #66 | BS1: #67 | BT1: #68 | BU1: #69 | BV1: #70 | BW1: #71 | BX1: #72 | BY1: #73 | BZ1: #74 | CA1: #75 | CB1: #76 | CC1: #77 | CD1: #78 | CE1: #79 | CF1: #80 | CG1: #81 | CH1: #82 | CI1: #83 | CJ1: #84 | CK1: #85 | CL1: #86 | CM1: #87 | CN1: #88 | CO1: #89 | CP1: #90 | CQ1: #91 | CR1: #92 | CS1: #93 | CT1: #94 | CU1: #95 | CV1: #96 | CW1: #97 | CX1: #98 | CY1: #99 | CZ1: #100 | DA1: #101 | DB1: #102 | DC1: #103 | DD1: #104 | DE1: #105 | DF1: #106 | DG1: #107 | DH1: #108 | DI1: #109 | DJ1: #110 | DK1: #111 | DL1: #112 | DM1: #113 | DN1: #114 | DO1: #115 | DP1: #116 | DQ1: #117 | DR1: #118 | DS1: #119 | DT1: #120 | DU1: #121 | DV1: #122 | DW1: #123 | DX1: #124 | DY1: #125 | DZ1: #126 | EA1: #127 | EB1: #128 | EC1: #129 | ED1: #130 | EE1: #131 | EF1: #132 | EG1: #133 | EH1: #134 | EI1: #135 | EJ1: #136 | EK1: #137 | EL1: #138 | EM1: #139 | EN1: #140 | EO1: #141 | EP1: #142 | EQ1: #143 | ER1: #144 | ES1: #145 | ET1: #146 | EU1: #147 | EV1: #148 | EW1: #149 | EX1: #150 | EY1: #151 | EZ1: #152 | FA1: #153 | FB1: #154 | FC1: #155 | FD1: #156 | FE1: #157 | FF1: #158 | FG1: #159 | FH1: #160 | FI1: #161 | FJ1: #162 | FK1: #163 | FL1: #164 | FM1: #165 | FN1: #166 | FO1: #167 | FP1: #168 | FQ1: #169 | FR1: #170 | FS1: #171 | FT1: #172 | FU1: #173 | FV1: #174 | FW1: #175 | FX1: #176 | FY1: #177 | FZ1: #178 | GA1: #179 | GB1: #180 | GC1: #181 | GD1: #182 | GE1: #183 | GF1: #184 | GG1: #185 | GH1: #186 | GI1: #187 | GJ1: #188 | GK1: #189 | GL1: #190 | GM1: #191 | GN1: #192 | GO1: #193 | GP1: #194 | GQ1: #195 | GR1: #196 | GS1: #197 | GT1: #198 | GU1: #199 | GV1: #200 | GW1: #201 | GX1: #202 | GY1: #203 | GZ1: #204 | HA1: #205 | HB1: #206 | HC1: #207 | HD1: #208 | HE1: #209 | HF1: #210 | HG1: #211 | HH1: #212 | HI1: #213 | HJ1: #214 | HK1: #215 | HL1: #216 | HM1: #217 | HN1: #218 | HO1: #219 | HP1: #220 | HQ1: #221 | HR1: #222 | HS1: #223 | HT1: #224 | HU1: #225 | HV1: #226 | HW1: #227 | HX1: #228 | HY1: #229 | HZ1: #230 | IA1: #231 | IB1: #232 | IC1: #233 | ID1: #234 | IE1: #235 | IF1: #236 | IG1: #237 | IH1: #238 | II1: #239 | IJ1: #240 | IK1: #241 | IL1: #242 | IM1: #243 | IN1: #244 | IO1: #245 | IP1: #246 | IQ1: #247 | IR1: #248 | IS1: #249 | IT1: #250 | IU1: #251 | IV1: #252 | IW1: #253 | IX1: #254 | IY1: #255 | IZ1: #256 | JA1: #257 | JB1: #258 | JC1: #259 | JD1: #260 | JE1: #261 | JF1: #262 | JG1: #263 | JH1: #264 | JI1: #265 | JJ1: #266 | JK1: #267 | JL1: #268 | JM1: #269 | JN1: #270 | JO1: #271 | JP1: #272 | JQ1: #273 | JR1: #274 | JS1: #275 | JT1: #276 | JU1: #277 | JV1: #278 | JW1: #279 | JX1: #280 | JY1: #281 | JZ1: #282 | KA1: #283 | KB1: #284 | KC1: #285 | KD1: #286 | KE1: #287 | KF1: #288 | KG1: #289 | KH1: #290 | KI1: #291 | KJ1: #292 | KK1: #293 | KL1: #294 | KM1: #295 | KN1: #296 | KO1: #297 | KP1: #298 | KQ1: #299 | KR1: #300 | KS1: #301 | KT1: #302 | KU1: #303 | KV1: #304 | KW1: #305 | KX1: #306 | KY1: #307 | KZ1: #308 | LA1: #309 | LB1: #310 | LC1: #311 | LD1: #312 | LE1: #313 | LF1: #314 | LG1: #315 | LH1: #316 | LI1: #317 | LJ1: #318 | LK1: #319 | LL1: #320 | LM1: #321 | LN1: #322 | LO1: #323 | LP1: #324 | LQ1: #325 | LR1: #326 | LS1: #327 | LT1: #328 | LU1: #329 | LV1: #330 | LW1: #331 | LX1: #332 | LY1: #333 | LZ1: #334 | MA1: #335 | MB1: #336 | MC1: #337 | MD1: #338 | ME1: #339 | MF1: #340 | MG1: #341 | MH1: #342 | MI1: #343 | MJ1: #344 | MK1: #345 | ML1: #346 | MM1: #347 | MN1: #348 | MO1: #349 | MP1: #350 | MQ1: #351 | MR1: #352 | MS1: #353 | MT1: #354 | MU1: #355 | MV1: #356 | MW1: #357 | MX1: #358 | MY1: #359 | MZ1: #360 | NA1: #361 | NB1: #362 | NC1: #363 | ND1: #364 | NE1: #365 | NF1: #366 | NG1: #367 | NH1: #368 | NI1: #369 | NJ1: #370 | NK1: #371 | NL1: #372 | NM1: #373 | NN1: #374 | NO1: #375 | NP1: #376 | NQ1: #377 | NR1: #378 | NS1: #379 | NT1: #380 | NU1: #381 | NV1: #382 | NW1: #383 | NX1: #384 | NY1: #385 | NZ1: #386 | OA1: #387 | OB1: #388 | OC1: #389 | OD1: #390 | OE1: #391 | OF1: #392 | OG1: #393 | OH1: #394 | OI1: #395 | OJ1: #396 | OK1: #397 | OL1: #398 | OM1: #399 | ON1: #400 | OO1: #401 | OP1: #402 | OQ1: #403 | OR1: #404 | OS1: #405 | OT1: #406 | OU1: #407 | OV1: #408 | OW1: #409 | OX1: #410 | OY1: #411 | OZ1: #412 | PA1: #413 | PB1: #414 | PC1: #415 | PD1: #416 | PE1: #417 | PF1: #418 | PG1: #419 | PH1: #420 | PI1: #421 | PJ1: #422 | PK1: #423 | PL1: #424 | PM1: #425 | PN1: #426 | PO1: #427 | PP1: #428 | PQ1: #429 | PR1: #430 | PS1: #431 | PT1: #432 | PU1: #433 | PV1: #434 | PW1: #435 | PX1: #436 | PY1: #437 | PZ1: #438 | QA1: #439 | QB1: #440 | QC1: #441 | QD1: #442 | QE1: #443 | QF1: #444 | QG1: #445 | QH1: #446 | QI1: #447 | QJ1: #448 | QK1: #449 | QL1: #450 | QM1: #451 | QN1: #452 | QO1: #453 | QP1: #454 | QQ1: #455 | QR1: #456 | QS1: #457 | QT1: #458 | QU1: #459 | QV1: #460 | QW1: #461 | QX1: #462 | QY1: #463 | QZ1: #464 | RA1: #465 | RB1: #466 | RC1: #467 | RD1: #468 | RE1: #469 | RF1: #470 | RG1: #471 | RH1: #472 | RI1: #473 | RJ1: #474 | RK1: #475 | RL1: #476 | RM1: #477 | RN1: #478 | RO1: #479 | RP1: #480 | RQ1: #481 | RR1: #482 | RS1: #483 | RT1: #484 | RU1: #485 | RV1: #486 | RW1: #487 | RX1: #488 | RY1: #489 | RZ1: #490 | SA1: #491 | SB1: #492 | SC1: #493 | SD1: #494 | SE1: #495 | SF1: #496 | SG1: #497 | SH1: #498 | SI1: #499 | SJ1: #500
B2: Dato  | E2: 45809 | F2: 45809 | G2: 45809 | H2: 45810 | I2: 45812 | J2: 45818 | K2: 45818 | L2: 45818 | M2: 45820 | N2: 45824 | O2: 45824 | P2: 45825 | Q2: 45825 | R2: 45825 | S2: 45826 | T2: 45826 | U2: 45826 | V2: 45839 | W2: 45839 | X2: 45839 | Y2: 45839 | Z2: 45848 | AA2: 45848 | AB2: 45852 | AC2: 45855 | AD2: 45870 | AE2: 45870 | AF2: 45870 | AG2: 45880 | AH2: 45880 | AI2: 45880 | AJ2: 45887 | AK2: 45887 | AL2: 45887 | AM2: 45889 | AN2: 45891 | AO2: 45894 | AP2: 45897 | AQ2: 45901 | AR2: 45901 | AS2: 45902 | AT2: 45905 | AU2: 45905 | AV2: 45912 | AW2: 45912 | AX2: 45912 | AY2: 45915 | AZ2: 45915 | BA2: 45917 | BB2: 45917 | BC2: 45918 | BD2: 45919 | BE2: 45919 | BF2: 45922 | BG2: 45922 | BH2: 45922 | BI2: 45926 | BJ2: 45926 | BK2: 45931 | BL2: 45667 | BM2: 45931 | BN2: 45931 | BO2: 45931 | BP2: 45943 | BQ2: 45944 | BR2: 45945 | BS2: 45947 | BT2: 45950 | BU2: 45958 | BV2: 45959 | BW2: 45961 | BX2: 45961 | BY2: 45962 | BZ2: 45962 | CA2: 45964 | CB2: 45975 | CC2: 45978 | CD2: 45982 | CE2: 45982 | CF2: 45982 | CG2: 45982 | CH2: 45982 | CI2: 45985 | CJ2: 45985 | CK2: 45987 | CL2: 45988
B3: Forklaring  | E3: Startkapital | F3: Medlemskontingenter Juni | G3: Merchsalg | H3: Omkostninger Juni | I3: Dominos | J3: Dominos | K3: Extra Majorstuen | L3: YouTube | M3: SumUp | N3: Waldm. Ellefsen AS | O3: Extra Majorstuen | P3: Clas Ohlson | Q3: Dominos | R3: Microsoft | S3: Refusjon Johannes | T3: Extra Majorstuen | U3: Kiwi Kringsjå | V3: Medlemskontingenter Juli | W3: Hyttetur | X3: Merchsalg | Y3: Omkostninger Juli | Z3: Oda | AA3: Rema 1000 Røakrysset | AB3: Oda | AC3: Microsoft | AD3: Medlemskontingenter August | AE3: Merchsalg | AF3: Omkostninger August | AG3: Hyperion Øst | AH3: Hyperion Øst | AI3: Oslostudentenes Idrettsklubb | AJ3: Hyperion Øst | AK3: Hyperion Øst | AL3: Microsoft | AM3: Jernia | AN3: Extra Majorstuen | AO3: Media Markt P365 | AP3: Hyperion | AQ3: Medlemskontingenter September | AR3: Merchsalg | AS3: Omkostninger September | AT3: Dpl Osl-Sentrum AS | AU3: Refusjon Bastian | AV3: Extra Majorstuen | AW3: Rema 1000 Majorstuen | AX3: Outland | AY3: Gamezone | AZ3: Outland | BA3: Dominos | BB3: Microsoft | BC3: IKEA Karl Johan | BD3: Skandi Mobile Expert | BE3: Extra Majorstuen | BF3: Ringo Majorstuen | BG3: Dominos | BH3: Extra Majorstuen | BI3: Refusjon Yunting CCC | BJ3: Refusjon Yuyan CCC | BK3: Medlemskontingenter Oktober | BL3: Merchsalg | BM3: Gangfest H25 | BN3: Refusjon Georgy | BO3: Omkostninger Oktober | BP3: Refusjon Bastian | BQ3: Dpl Osl-Sentrum AS | BR3: Dominos | BS3: Microsoft | BT3: Alibaba | BU3: AliExpress | BV3: Refusjon Bastian | BW3: Dpl Osl-Sentrum AS | BX3: Refusjon Georgy | BY3: Medlemskontingenter November | BZ3: Merchsalg | CA3: Omkostninger November | CB3: Alibaba | CC3: Microsoft | CD3: Clas Ohlson | CE3: Meny Colosseum | CF3: AliExpress | CG3: Vinmonopolet | CH3: Dominos | CI3: Dominos | CJ3: Refusjon Johannes | CK3: Dominos | CL3: Hyperion
B4: BALANSE | C4: IB | D4: UB | E4: #1 | F4: #2 | G4: #3 | H4: #4 | I4: #5 | J4: #6 | K4: #7 | L4: #8 | M4: #9 | N4: #10 | O4: #11 | P4: #12 | Q4: #13 | R4: #14 | S4: #15 | T4: #16 | U4: #17 | V4: #18 | W4: #19 | X4: #20 | Y4: #21 | Z4: #22 | AA4: #23 | AB4: #24 | AC4: #25 | AD4: #26 | AE4: #27 | AF4: #28 | AG4: #29 | AH4: #30 | AI4: #31 | AJ4: #32 | AK4: #33 | AL4: #34 | AM4: #35 | AN4: #36 | AO4: #37 | AP4: #38 | AQ4: #39 | AR4: #40 | AS4: #41 | AT4: #42 | AU4: #43 | AV4: #44 | AW4: #45 | AX4: #46 | AY4: #47 | AZ4: #48 | BA4: #49 | BB4: #50 | BC4: #51 | BD4: #52 | BE4: #53 | BF4: #54 | BG4: #55 | BH4: #56 | BI4: #57 | BJ4: #58 | BK4: #59 | BL4: #60 | BM4: #61 | BN4: #62 | BO4: #63 | BP4: #64 | BQ4: #65 | BR4: #66 | BS4: #67 | BT4: #68 | BU4: #69 | BV4: #70 | BW4: #71 | BX4: #72 | BY4: #73 | BZ4: #74 | CA4: #75 | CB4: #76 | CC4: #77 | CD4: #78 | CE4: #79 | CF4: #80 | CG4: #81 | CH4: #82 | CI4: #83 | CJ4: #84 | CK4: #85 | CL4: #86 | CM4: #87 | CN4: #88 | CO4: #89 | CP4: #90 | CQ4: #91 | CR4: #92 | CS4: #93 | CT4: #94 | CU4: #95 | CV4: #96 | CW4: #97 | CX4: #98 | CY4: #99 | CZ4: #100 | DA4: #101 | DB4: #102 | DC4: #103 | DD4: #104 | DE4: #105 | DF4: #106 | DG4: #107 | DH4: #108 | DI4: #109 | DJ4: #110 | DK4: #111 | DL4: #112 | DM4: #113 | DN4: #114 | DO4: #115 | DP4: #116 | DQ4: #117 | DR4: #118 | DS4: #119 | DT4: #120 | DU4: #121 | DV4: #122 | DW4: #123 | DX4: #124 | DY4: #125 | DZ4: #126 | EA4: #127 | EB4: #128 | EC4: #129 | ED4: #130 | EE4: #131 | EF4: #132 | EG4: #133 | EH4: #134 | EI4: #135 | EJ4: #136 | EK4: #137 | EL4: #138 | EM4: #139 | EN4: #140 | EO4: #141 | EP4: #142 | EQ4: #143 | ER4: #144 | ES4: #145 | ET4: #146 | EU4: #147 | EV4: #148 | EW4: #149 | EX4: #150 | EY4: #151 | EZ4: #152 | FA4: #153 | FB4: #154 | FC4: #155 | FD4: #156 | FE4: #157 | FF4: #158 | FG4: #159 | FH4: #160 | FI4: #161 | FJ4: #162 | FK4: #163 | FL4: #164 | FM4: #165 | FN4: #166 | FO4: #167 | FP4: #168 | FQ4: #169 | FR4: #170 | FS4: #171 | FT4: #172 | FU4: #173 | FV4: #174 | FW4: #175 | FX4: #176 | FY4: #177 | FZ4: #178 | GA4: #179 | GB4: #180 | GC4: #181 | GD4: #182 | GE4: #183 | GF4: #184 | GG4: #185 | GH4: #186 | GI4: #187 | GJ4: #188 | GK4: #189 | GL4: #190 | GM4: #191 | GN4: #192 | GO4: #193 | GP4: #194 | GQ4: #195 | GR4: #196 | GS4: #197 | GT4: #198 | GU4: #199 | GV4: #200 | GW4: #201 | GX4: #202 | GY4: #203 | GZ4: #204 | HA4: #205 | HB4: #206 | HC4: #207 | HD4: #208 | HE4: #209 | HF4: #210 | HG4: #211 | HH4: #212 | HI4: #213 | HJ4: #214 | HK4: #215 | HL4: #216 | HM4: #217 | HN4: #218 | HO4: #219 | HP4: #220 | HQ4: #221 | HR4: #222 | HS4: #223 | HT4: #224 | HU4: #225 | HV4: #226 | HW4: #227 | HX4: #228 | HY4: #229 | HZ4: #230 | IA4: #231 | IB4: #232 | IC4: #233 | ID4: #234 | IE4: #235 | IF4: #236 | IG4: #237 | IH4: #238 | II4: #239 | IJ4: #240 | IK4: #241 | IL4: #242 | IM4: #243 | IN4: #244 | IO4: #245 | IP4: #246 | IQ4: #247 | IR4: #248 | IS4: #249 | IT4: #250 | IU4: #251 | IV4: #252 | IW4: #253 | IX4: #254 | IY4: #255 | IZ4: #256 | JA4: #257 | JB4: #258 | JC4: #259 | JD4: #260 | JE4: #261 | JF4: #262 | JG4: #263 | JH4: #264 | JI4: #265 | JJ4: #266 | JK4: #267 | JL4: #268 | JM4: #269 | JN4: #270 | JO4: #271 | JP4: #272 | JQ4: #273 | JR4: #274 | JS4: #275 | JT4: #276 | JU4: #277 | JV4: #278 | JW4: #279 | JX4: #280 | JY4: #281 | JZ4: #282 | KA4: #283 | KB4: #284 | KC4: #285 | KD4: #286 | KE4: #287 | KF4: #288 | KG4: #289 | KH4: #290 | KI4: #291 | KJ4: #292 | KK4: #293 | KL4: #294 | KM4: #295 | KN4: #296 | KO4: #297 | KP4: #298 | KQ4: #299 | KR4: #300 | KS4: #301 | KT4: #302 | KU4: #303 | KV4: #304 | KW4: #305 | KX4: #306 | KY4: #307 | KZ4: #308 | LA4: #309 | LB4: #310 | LC4: #311 | LD4: #312 | LE4: #313 | LF4: #314 | LG4: #315 | LH4: #316 | LI4: #317 | LJ4: #318 | LK4: #319 | LL4: #320 | LM4: #321 | LN4: #322 | LO4: #323 | LP4: #324 | LQ4: #325 | LR4: #326 | LS4: #327 | LT4: #328 | LU4: #329 | LV4: #330 | LW4: #331 | LX4: #332 | LY4: #333 | LZ4: #334 | MA4: #335 | MB4: #336 | MC4: #337 | MD4: #338 | ME4: #339 | MF4: #340 | MG4: #341 | MH4: #342 | MI4: #343 | MJ4: #344 | MK4: #345 | ML4: #346 | MM4: #347 | MN4: #348 | MO4: #349 | MP4: #350 | MQ4: #351 | MR4: #352 | MS4: #353 | MT4: #354 | MU4: #355 | MV4: #356 | MW4: #357 | MX4: #358 | MY4: #359 | MZ4: #360 | NA4: #361 | NB4: #362 | NC4: #363 | ND4: #364 | NE4: #365 | NF4: #366 | NG4: #367 | NH4: #368 | NI4: #369 | NJ4: #370 | NK4: #371 | NL4: #372 | NM4: #373 | NN4: #374 | NO4: #375 | NP4: #376 | NQ4: #377 | NR4: #378 | NS4: #379 | NT4: #380 | NU4: #381 | NV4: #382 | NW4: #383 | NX4: #384 | NY4: #385 | NZ4: #386 | OA4: #387 | OB4: #388 | OC4: #389 | OD4: #390 | OE4: #391 | OF4: #392 | OG4: #393 | OH4: #394 | OI4: #395 | OJ4: #396 | OK4: #397 | OL4: #398 | OM4: #399 | ON4: #400 | OO4: #401 | OP4: #402 | OQ4: #403 | OR4: #404 | OS4: #405 | OT4: #406 | OU4: #407 | OV4: #408 | OW4: #409 | OX4: #410 | OY4: #411 | OZ4: #412 | PA4: #413 | PB4: #414 | PC4: #415 | PD4: #416 | PE4: #417 | PF4: #418 | PG4: #419 | PH4: #420 | PI4: #421 | PJ4: #422 | PK4: #423 | PL4: #424 | PM4: #425 | PN4: #426 | PO4: #427 | PP4: #428 | PQ4: #429 | PR4: #430 | PS4: #431 | PT4: #432 | PU4: #433 | PV4: #434 | PW4: #435 | PX4: #436 | PY4: #437 | PZ4: #438 | QA4: #439 | QB4: #440 | QC4: #441 | QD4: #442 | QE4: #443 | QF4: #444 | QG4: #445 | QH4: #446 | QI4: #447 | QJ4: #448 | QK4: #449 | QL4: #450 | QM4: #451 | QN4: #452 | QO4: #453 | QP4: #454 | QQ4: #455 | QR4: #456 | QS4: #457 | QT4: #458 | QU4: #459 | QV4: #460 | QW4: #461 | QX4: #462 | QY4: #463 | QZ4: #464 | RA4: #465 | RB4: #466 | RC4: #467 | RD4: #468 | RE4: #469 | RF4: #470 | RG4: #471 | RH4: #472 | RI4: #473 | RJ4: #474 | RK4: #475 | RL4: #476 | RM4: #477 | RN4: #478 | RO4: #479 | RP4: #480 | RQ4: #481 | RR4: #482 | RS4: #483 | RT4: #484 | RU4: #485 | RV4: #486 | RW4: #487 | RX4: #488 | RY4: #489 | RZ4: #490 | SA4: #491 | SB4: #492 | SC4: #493 | SD4: #494 | SE4: #495 | SF4: #496 | SG4: #497 | SH4: #498 | SI4: #499 | SJ4: #500
B5: Eiendeler
A6: + | B6: 1300 Lån til eksterne | D6: =C6+SUM(E6:SJ6) -> 0
A7: + | B7: 1400 Varelager | D7: =C7+SUM(E7:SJ7) -> 0
A8: + | B8: 1500 Fordringer | D8: =C8+SUM(E8:SJ8) -> 0
A9: + | B9: 1550 Interne fordringer | D9: =C9+SUM(E9:SJ9) -> 0
A10: + | B10: 1900 Kontanter | D10: =C10+SUM(E10:SJ10) -> 0
A11: + | B11: 1910 Brukskonto | D11: =C11+SUM(E11:SJ11) -> 120240.12 | F11: 600 | G11: 950 | H11: -37.5 | I11: -502.5 | J11: -2748 | K11: -337.4 | L11: -49 | M11: 651.15 | N11: -930 | O11: -298.26 | P11: -459.7 | Q11: -524 | R11: -179 | S11: -554 | T11: -548.05 | U11: -285.6 | V11: 200 | W11: 900 | X11: 1000 | Y11: -110.5 | Z11: -4122.3 | AA11: -39 | AB11: -816 | AC11: -179 | AD11: 1000 | AE11: 150 | AF11: -10 | AG11: 35381.12 | AH11: 88686.09 | AI11: -9000 | AJ11: 4060.13 | AK11: 689.49 | AL11: -179 | AM11: -99.5 | AN11: -509 | AO11: -6922.94 | AP11: -4520.44 | AQ11: 1050 | AR11: 400 | AS11: -130.5 | AT11: -347.5 | AU11: -494.3 | AV11: -597.5 | AW11: -145.7 | AX11: -5091.3 | AY11: -5878 | AZ11: -1033.2 | BA11: -317.5 | BB11: -179 | BC11: -27 | BD11: -1199 | BE11: -294.5 | BF11: -903.8 | BG11: -2514 | BH11: -129.6 | BI11: -4102.9 | BJ11: -1134.6 | BK11: 300 | BL11: 300 | BM11: 2298 | BN11: -4421.9 | BO11: -139.5 | BP11: -331.9 | BQ11: -312.5 | BR11: -381 | BS11: -179 | BT11: -6653.07 | BU11: -1130.04 | BV11: -823.6 | BW11: -2531 | BX11: -1415 | BY11: 200 | CA11: -125 | CB11: 1547.58 | CC11: -309 | CD11: -649.5 | CE11: -757.51 | CF11: 1130.04 | CG11: -566.8 | CH11: -309 | CI11: -329 | CJ11: -1409 | CK11: -209 | CL11: 60209.43
A12: + | B12: 1920 Sparekonto | D12: =C12+SUM(E12:SJ12) -> 0
B13: Egenkapital og gjeld
A14: - | B14: 2050 Egenkapital | D14: =C14+SUM(E14:SJ14) -> 83181.49 | E14: 83181.49
A15: - | B15: 2400 Leverandørgjeld | D15: =C15+SUM(E15:SJ15) -> 0
A16: - | B16: 2910 Gjeld til interne (utlegg) | D16: =C16+SUM(E16:SJ16) -> 0
A17: - | B17: 2950 Annen gjeld | D17: =C17+SUM(E17:SJ17) -> 0
B18: RESULTAT | E18: #1 | F18: #2 | G18: #3 | H18: #4 | I18: #5 | J18: #6 | K18: #7 | L18: #8 | M18: #9 | N18: #10 | O18: #11 | P18: #12 | Q18: #13 | R18: #14 | S18: #15 | T18: #16 | U18: #17 | V18: #18 | W18: #19 | X18: #20 | Y18: #21 | Z18: #22 | AA18: #23 | AB18: #24 | AC18: #25 | AD18: #26 | AE18: #27 | AF18: #28 | AG18: #29 | AH18: #30 | AI18: #31 | AJ18: #32 | AK18: #33 | AL18: #34 | AM18: #35 | AN18: #36 | AO18: #37 | AP18: #38 | AQ18: #39 | AR18: #40 | AS18: #41 | AT18: #42 | AU18: #43 | AV18: #44 | AW18: #45 | AX18: #46 | AY18: #47 | AZ18: #48 | BA18: #49 | BB18: #50 | BC18: #51 | BD18: #52 | BE18: #53 | BF18: #54 | BG18: #55 | BH18: #56 | BI18: #57 | BJ18: #58 | BK18: #59 | BL18: #60 | BM18: #61 | BN18: #62 | BO18: #63 | BP18: #64 | BQ18: #65 | BR18: #66 | BS18: #67 | BT18: #68 | BU18: #69 | BV18: #70 | BW18: #71 | BX18: #72 | BY18: #73 | BZ18: #74 | CA18: #75 | CB18: #76 | CC18: #77 | CD18: #78 | CE18: #79 | CF18: #80 | CG18: #81 | CH18: #82 | CI18: #83 | CJ18: #84 | CK18: #85 | CL18: #86 | CM18: #87 | CN18: #88 | CO18: #89 | CP18: #90 | CQ18: #91 | CR18: #92 | CS18: #93 | CT18: #94 | CU18: #95 | CV18: #96 | CW18: #97 | CX18: #98 | CY18: #99 | CZ18: #100 | DA18: #101 | DB18: #102 | DC18: #103 | DD18: #104 | DE18: #105 | DF18: #106 | DG18: #107 | DH18: #108 | DI18: #109 | DJ18: #110 | DK18: #111 | DL18: #112 | DM18: #113 | DN18: #114 | DO18: #115 | DP18: #116 | DQ18: #117 | DR18: #118 | DS18: #119 | DT18: #120 | DU18: #121 | DV18: #122 | DW18: #123 | DX18: #124 | DY18: #125 | DZ18: #126 | EA18: #127 | EB18: #128 | EC18: #129 | ED18: #130 | EE18: #131 | EF18: #132 | EG18: #133 | EH18: #134 | EI18: #135 | EJ18: #136 | EK18: #137 | EL18: #138 | EM18: #139 | EN18: #140 | EO18: #141 | EP18: #142 | EQ18: #143 | ER18: #144 | ES18: #145 | ET18: #146 | EU18: #147 | EV18: #148 | EW18: #149 | EX18: #150 | EY18: #151 | EZ18: #152 | FA18: #153 | FB18: #154 | FC18: #155 | FD18: #156 | FE18: #157 | FF18: #158 | FG18: #159 | FH18: #160 | FI18: #161 | FJ18: #162 | FK18: #163 | FL18: #164 | FM18: #165 | FN18: #166 | FO18: #167 | FP18: #168 | FQ18: #169 | FR18: #170 | FS18: #171 | FT18: #172 | FU18: #173 | FV18: #174 | FW18: #175 | FX18: #176 | FY18: #177 | FZ18: #178 | GA18: #179 | GB18: #180 | GC18: #181 | GD18: #182 | GE18: #183 | GF18: #184 | GG18: #185 | GH18: #186 | GI18: #187 | GJ18: #188 | GK18: #189 | GL18: #190 | GM18: #191 | GN18: #192 | GO18: #193 | GP18: #194 | GQ18: #195 | GR18: #196 | GS18: #197 | GT18: #198 | GU18: #199 | GV18: #200 | GW18: #201 | GX18: #202 | GY18: #203 | GZ18: #204 | HA18: #205 | HB18: #206 | HC18: #207 | HD18: #208 | HE18: #209 | HF18: #210 | HG18: #211 | HH18: #212 | HI18: #213 | HJ18: #214 | HK18: #215 | HL18: #216 | HM18: #217 | HN18: #218 | HO18: #219 | HP18: #220 | HQ18: #221 | HR18: #222 | HS18: #223 | HT18: #224 | HU18: #225 | HV18: #226 | HW18: #227 | HX18: #228 | HY18: #229 | HZ18: #230 | IA18: #231 | IB18: #232 | IC18: #233 | ID18: #234 | IE18: #235 | IF18: #236 | IG18: #237 | IH18: #238 | II18: #239 | IJ18: #240 | IK18: #241 | IL18: #242 | IM18: #243 | IN18: #244 | IO18: #245 | IP18: #246 | IQ18: #247 | IR18: #248 | IS18: #249 | IT18: #250 | IU18: #251 | IV18: #252 | IW18: #253 | IX18: #254 | IY18: #255 | IZ18: #256 | JA18: #257 | JB18: #258 | JC18: #259 | JD18: #260 | JE18: #261 | JF18: #262 | JG18: #263 | JH18: #264 | JI18: #265 | JJ18: #266 | JK18: #267 | JL18: #268 | JM18: #269 | JN18: #270 | JO18: #271 | JP18: #272 | JQ18: #273 | JR18: #274 | JS18: #275 | JT18: #276 | JU18: #277 | JV18: #278 | JW18: #279 | JX18: #280 | JY18: #281 | JZ18: #282 | KA18: #283 | KB18: #284 | KC18: #285 | KD18: #286 | KE18: #287 | KF18: #288 | KG18: #289 | KH18: #290 | KI18: #291 | KJ18: #292 | KK18: #293 | KL18: #294 | KM18: #295 | KN18: #296 | KO18: #297 | KP18: #298 | KQ18: #299 | KR18: #300 | KS18: #301 | KT18: #302 | KU18: #303 | KV18: #304 | KW18: #305 | KX18: #306 | KY18: #307 | KZ18: #308 | LA18: #309 | LB18: #310 | LC18: #311 | LD18: #312 | LE18: #313 | LF18: #314 | LG18: #315 | LH18: #316 | LI18: #317 | LJ18: #318 | LK18: #319 | LL18: #320 | LM18: #321 | LN18: #322 | LO18: #323 | LP18: #324 | LQ18: #325 | LR18: #326 | LS18: #327 | LT18: #328 | LU18: #329 | LV18: #330 | LW18: #331 | LX18: #332 | LY18: #333 | LZ18: #334 | MA18: #335 | MB18: #336 | MC18: #337 | MD18: #338 | ME18: #339 | MF18: #340 | MG18: #341 | MH18: #342 | MI18: #343 | MJ18: #344 | MK18: #345 | ML18: #346 | MM18: #347 | MN18: #348 | MO18: #349 | MP18: #350 | MQ18: #351 | MR18: #352 | MS18: #353 | MT18: #354 | MU18: #355 | MV18: #356 | MW18: #357 | MX18: #358 | MY18: #359 | MZ18: #360 | NA18: #361 | NB18: #362 | NC18: #363 | ND18: #364 | NE18: #365 | NF18: #366 | NG18: #367 | NH18: #368 | NI18: #369 | NJ18: #370 | NK18: #371 | NL18: #372 | NM18: #373 | NN18: #374 | NO18: #375 | NP18: #376 | NQ18: #377 | NR18: #378 | NS18: #379 | NT18: #380 | NU18: #381 | NV18: #382 | NW18: #383 | NX18: #384 | NY18: #385 | NZ18: #386 | OA18: #387 | OB18: #388 | OC18: #389 | OD18: #390 | OE18: #391 | OF18: #392 | OG18: #393 | OH18: #394 | OI18: #395 | OJ18: #396 | OK18: #397 | OL18: #398 | OM18: #399 | ON18: #400 | OO18: #401 | OP18: #402 | OQ18: #403 | OR18: #404 | OS18: #405 | OT18: #406 | OU18: #407 | OV18: #408 | OW18: #409 | OX18: #410 | OY18: #411 | OZ18: #412 | PA18: #413 | PB18: #414 | PC18: #415 | PD18: #416 | PE18: #417 | PF18: #418 | PG18: #419 | PH18: #420 | PI18: #421 | PJ18: #422 | PK18: #423 | PL18: #424 | PM18: #425 | PN18: #426 | PO18: #427 | PP18: #428 | PQ18: #429 | PR18: #430 | PS18: #431 | PT18: #432 | PU18: #433 | PV18: #434 | PW18: #435 | PX18: #436 | PY18: #437 | PZ18: #438 | QA18: #439 | QB18: #440 | QC18: #441 | QD18: #442 | QE18: #443 | QF18: #444 | QG18: #445 | QH18: #446 | QI18: #447 | QJ18: #448 | QK18: #449 | QL18: #450 | QM18: #451 | QN18: #452 | QO18: #453 | QP18: #454 | QQ18: #455 | QR18: #456 | QS18: #457 | QT18: #458 | QU18: #459 | QV18: #460 | QW18: #461 | QX18: #462 | QY18: #463 | QZ18: #464 | RA18: #465 | RB18: #466 | RC18: #467 | RD18: #468 | RE18: #469 | RF18: #470 | RG18: #471 | RH18: #472 | RI18: #473 | RJ18: #474 | RK18: #475 | RL18: #476 | RM18: #477 | RN18: #478 | RO18: #479 | RP18: #480 | RQ18: #481 | RR18: #482 | RS18: #483 | RT18: #484 | RU18: #485 | RV18: #486 | RW18: #487 | RX18: #488 | RY18: #489 | RZ18: #490 | SA18: #491 | SB18: #492 | SC18: #493 | SD18: #494 | SE18: #495 | SF18: #496 | SG18: #497 | SH18: #498 | SI18: #499 | SJ18: #500
B19: Inntekter
A20: - | B20: 3000 Salgsinntekter | D20: =C20+SUM(E20:SJ20) -> -3599.15 | G20: -950 | M20: -651.15 | X20: -1000 | AE20: -150 | AR20: -400 | BL20: -300 | BM20: -148
A21: - | B21: 3100 Medlemskontingent | D21: =C21+SUM(E21:SJ21) -> -3350 | F21: -600 | V21: -200 | AD21: -1000 | AQ21: -1050 | BK21: -300 | BY21: -200
A22: - | B22: 3200 Billettinntekter | D22: =C22+SUM(E22:SJ22) -> -3050 | W22: -900 | BM22: -2150
A23: - | B23: 3400 Støtte fra Oslostøtte | D23: =C23+SUM(E23:SJ23) -> -88686.09 | AH23: -88686.09
A24: - | B24: 3410 Støtte fra Fri Fond | D24: =C24+SUM(E24:SJ24) -> -60209.43 | CL24: -60209.43
A25: - | B25: 3420 Støtte fra annen støtteordning | D25: =C25+SUM(E25:SJ25) -> -40130.74 | AG25: -35381.12 | AJ25: -4060.13 | AK25: -689.49
A26: - | B26: 3900 Annen inntekt | D26: =C26+SUM(E26:SJ26) -> -2677.62 | CB26: -1547.58 | CF26: -1130.04
A27: - | B27: 8050 Renteinntekter | D27: =C27+SUM(E27:SJ27) -> 0
B28: Kostnader
A29: + | B29: 4000 Varekjøp til videresalg | D29: =C29+SUM(E29:SJ29) -> 4938.3 | Z29: 4122.3 | AB29: 816
A30: + | B30: 4300 Forbruk varelager | D30: =C30+SUM(E30:SJ30) -> 0
A31: + | B31: 4390 Beholdningsendring varer | D31: =C31+SUM(E31:SJ31) -> 0
A32: + | B32: 5000 Skattefritt honorar, interne | D32: =C32+SUM(E32:SJ32) -> 0
A33: + | B33: 5050 Skattefritt honorar, eksterne | D33: =C33+SUM(E33:SJ33) -> 0
A34: + | B34: 5700 Støtte til andre foreninger | D34: =C34+SUM(E34:SJ34) -> 0
A35: + | B35: 5900 Gaver ansatte | D35: =C35+SUM(E35:SJ35) -> 0
A36: + | B36: 5910 Mat og drikke til frivillige | D36: =C36+SUM(E36:SJ36) -> 638 | CH36: 309 | CI36: 329
A37: + | B37: 5920 Mat og drikke til styret | D37: =C37+SUM(E37:SJ37) -> 2989 | I37: 502.5 | Q37: 524 | AT37: 347.5 | BA37: 317.5 | BN37: 395 | BQ37: 312.5 | BR37: 381 | CK37: 209
A38: + | B38: 6300 Leie av lokaler | D38: =C38+SUM(E38:SJ38) -> 0
A39: + | B39: 6450 Inventar | D39: =C39+SUM(E39:SJ39) -> 12656 | S39: 554 | AM39: 99.5 | AX39: 5091.3 | AY39: 5878 | AZ39: 1033.2
A40: + | B40: 6550 Driftsmaterialer | D40: =C40+SUM(E40:SJ40) -> 0
...

Sheet Resultatrapport
B3: [i]
C6: RESULTATRAPPORT
C9: =Oversikt!C8 -> Høst 2025
C11: Inntekter
C12: =Regnskap!B20 -> 3000 Salgsinntekter | D12: =-VLOOKUP(C12,Regnskap,3,FALSE) -> 3599.15
C13: =Regnskap!B21 -> 3100 Medlemskontingent | D13: =-VLOOKUP(C13,Regnskap,3,FALSE) -> 3350
C14: =Regnskap!B22 -> 3200 Billettinntekter | D14: =-VLOOKUP(C14,Regnskap,3,FALSE) -> 3050
C15: =Regnskap!B23 -> 3400 Støtte fra Oslostøtte | D15: =-VLOOKUP(C15,Regnskap,3,FALSE) -> 88686.09
C16: =Regnskap!B24 -> 3410 Støtte fra Fri Fond | D16: =-VLOOKUP(C16,Regnskap,3,FALSE) -> 60209.43
C17: =Regnskap!B25 -> 3420 Støtte fra annen støtteordning | D17: =-VLOOKUP(C17,Regnskap,3,FALSE) -> 40130.74
C18: =Regnskap!B26 -> 3900 Annen inntekt | D18: =-VLOOKUP(C18,Regnskap,3,FALSE) -> 2677.62
C19: =Regnskap!B27 -> 8050 Renteinntekter | D19: =-VLOOKUP(C19,Regnskap,3,FALSE) -> 0
C20: Sum inntekter | D20: =SUM(D12:D19) -> 201703.03
C22: Kostnader
C23: =Regnskap!B29 -> 4000 Varekjøp til videresalg | D23: =VLOOKUP(C23,Regnskap,3,FALSE) -> 4938.3
C24: =Regnskap!B30 -> 4300 Forbruk varelager | D24: =VLOOKUP(C24,Regnskap,3,FALSE) -> 0
C25: =Regnskap!B31 -> 4390 Beholdningsendring varer | D25: =VLOOKUP(C25,Regnskap,3,FALSE) -> 0
C26: =Regnskap!B32 -> 5000 Skattefritt honorar, interne | D26: =VLOOKUP(C26,Regnskap,3,FALSE) -> 0
C27: =Regnskap!B33 -> 5050 Skattefritt honorar, eksterne | D27: =VLOOKUP(C27,Regnskap,3,FALSE) -> 0
C28: =Regnskap!B34 -> 5700 Støtte til andre foreninger | D28: =VLOOKUP(C28,Regnskap,3,FALSE) -> 0
C29: =Regnskap!B35 -> 5900 Gaver ansatte | D29: =VLOOKUP(C29,Regnskap,3,FALSE) -> 0
C30: =Regnskap!B36 -> 5910 Mat og drikke til frivillige | D30: =VLOOKUP(C30,Regnskap,3,FALSE) -> 638
C31: =Regnskap!B37 -> 5920 Mat og drikke til styret | D31: =VLOOKUP(C31,Regnskap,3,FALSE) -> 2989
C32: =Regnskap!B38 -> 6300 Leie av lokaler | D32: =VLOOKUP(C32,Regnskap,3,FALSE) -> 0
C33: =Regnskap!B39 -> 6450 Inventar | D33: =VLOOKUP(C33,Regnskap,3,FALSE) -> 12656
C34: =Regnskap!B40 -> 6550 Driftsmaterialer | D34: =VLOOKUP(C34,Regnskap,3,FALSE) -> 0
... C54: =Regnskap!B60 -> 8150 Rentekostnader | D54: =VLOOKUP(C54,Regnskap,3,FALSE) -> 0
C55: Sum utgifter | D55: =SUM(D23:D54) -> 81462.91
C57: PERIODENS RESULTAT | D57: =D20-D55 -> 120240.12

Sheet Budsjett
B3: [i]
C4: BUDSJETT
C11: Inntekter | D11: =Oversikt!$C$8 -> Høst 2025 | E11: Vår 2026 | F11: Kommentar
C12: =Regnskap!B20 -> 3000 Salgsinntekter | D12: =-VLOOKUP(C12,Regnskap,3,FALSE) -> 3599.15 | E12: 2500
C13: =Regnskap!B21 -> 3100 Medlemskontingent | D13: =-VLOOKUP(C13,Regnskap,3,FALSE) -> 3350 | E13: 6000
C14: =Regnskap!B22 -> 3200 Billettinntekter | D14: =-VLOOKUP(C14,Regnskap,3,FALSE) -> 3050 | E14: 2500
C15: =Regnskap!B23 -> 3400 Støtte fra Oslostøtte | D15: =-VLOOKUP(C15,Regnskap,3,FALSE) -> 88686.09 | E15: 0 | F15: Forventer ikke noe støtte neste semester
C16: =Regnskap!B24 -> 3410 Støtte fra Fri Fond | D16: =-VLOOKUP(C16,Regnskap,3,FALSE) -> 60209.43 | E16: 0
C17: =Regnskap!B25 -> 3420 Støtte fra annen støtteordning | D17: =-VLOOKUP(C17,Regnskap,3,FALSE) -> 40130.74 | E17: 0
C18: =Regnskap!B26 -> 3900 Annen inntekt | D18: =-VLOOKUP(C18,Regnskap,3,FALSE) -> 2677.62 | E18: 0 | F18: Refunds
C19: =Regnskap!B27 -> 8050 Renteinntekter | D19: =-VLOOKUP(C19,Regnskap,3,FALSE) -> 0
C20: Sum inntekter | D20: =SUM(D12:D19) -> 201703.03 | E20: =SUM(E12:E19) -> 11000
C22: Kostnader | D22: =D11 -> Høst 2025 | E22: =E11 -> Vår 2026 | F22: Kommentar
C23: =Regnskap!B29 -> 4000 Varekjøp til videresalg | D23: =VLOOKUP(C23,Regnskap,3,FALSE) -> 4938.3 | E23: 5000
C24: =Regnskap!B30 -> 4300 Forbruk varelager | D24: =VLOOKUP(C24,Regnskap,3,FALSE) -> 0
C25: =Regnskap!B31 -> 4390 Beholdningsendring varer | D25: =VLOOKUP(C25,Regnskap,3,FALSE) -> 0
C26: =Regnskap!B32 -> 5000 Skattefritt honorar, interne | D26: =VLOOKUP(C26,Regnskap,3,FALSE) -> 0
C27: =Regnskap!B33 -> 5050 Skattefritt honorar, eksterne | D27: =VLOOKUP(C27,Regnskap,3,FALSE) -> 0
C28: =Regnskap!B34 -> 5700 Støtte til andre foreninger | D28: =VLOOKUP(C28,Regnskap,3,FALSE) -> 0
C29: =Regnskap!B35 -> 5900 Gaver ansatte | D29: =VLOOKUP(C29,Regnskap,3,FALSE) -> 0
C30: =Regnskap!B36 -> 5910 Mat og drikke til frivillige | D30: =VLOOKUP(C30,Regnskap,3,FALSE) -> 638 | E30: 1300 | F30: Det var crazy week uka gangfest tok sted
C31: =Regnskap!B37 -> 5920 Mat og drikke til styret | D31: =VLOOKUP(C31,Regnskap,3,FALSE) -> 2989 | E31: 3000
C32: =Regnskap!B38 -> 6300 Leie av lokaler | D32: =VLOOKUP(C32,Regnskap,3,FALSE) -> 0
C33: =Regnskap!B39 -> 6450 Inventar | D33: =VLOOKUP(C33,Regnskap,3,FALSE) -> 12656 | E33: 20000 | F33: FLERE BRETTSPILL*!!! (*: og andre ting)
C34: =Regnskap!B40 -> 6550 Driftsmaterialer | D34: =VLOOKUP(C34,Regnskap,3,FALSE) -> 0
C35: =Regnskap!B41 -> 6551 Datautstyr | D35: =VLOOKUP(C35,Regnskap,3,FALSE) -> 8331.94 | E35: 7500 | F35: Oppgradere pc-er
C36: =Regnskap!B42 -> 6552 Programvarer | D36: =VLOOKUP(C36,Regnskap,3,FALSE) -> 1204 | E36: 3600 | F36: Årlig PS-plus + månedlig game pass
C37: =Regnskap!B43 -> 6560 Rekvisita | D37: =VLOOKUP(C37,Regnskap,3,FALSE) -> 0
C38: =Regnskap!B44 -> 6590 Annen driftskostnad | D38: =VLOOKUP(C38,Regnskap,3,FALSE) -> 10238 | E38: 1000
C39: =Regnskap!B45 -> 6720 Økonomiske og juridiske tjenester | D39: =VLOOKUP(C39,Regnskap,3,FALSE) -> 4520.44 | E39: 0 | F39: Tilbakebetaling til Hyperion
C40: =Regnskap!B46 -> 6750 Arrangementkostnader | D40: =VLOOKUP(C40,Regnskap,3,FALSE) -> 26145.42 | E40: 27500
C41: =Regnskap!B47 -> 6755 Artist/underholdningshonorar | D41: =VLOOKUP(C41,Regnskap,3,FALSE) -> 0
C42: =Regnskap!B48 -> 6790 Andre fremmedtjenester | D42: =VLOOKUP(C42,Regnskap,3,FALSE) -> 8762.11 | E42: 5000
C43: =Regnskap!B49 -> 6800 Kontorrekvisita | D43: =VLOOKUP(C43,Regnskap,3,FALSE) -> 486.7 | E43: 30000 | F43: STORE PLANER FOR KONTORET!
C44: =Regnskap!B50 -> 6815 Internett | D44: =VLOOKUP(C44,Regnskap,3,FALSE) -> 0
C45: =Regnskap!B51 -> 6890 Annen kontorkostnad | D45: =VLOOKUP(C45,Regnskap,3,FALSE) -> 0
C46: =Regnskap!B52 -> 6900 Telefon | D46: =VLOOKUP(C46,Regnskap,3,FALSE) -> 0
C47: =Regnskap!B53 -> 6940 Porto | D47: =VLOOKUP(C47,Regnskap,3,FALSE) -> 0
C48: =Regnskap!B54 -> 7100 Reisekostnad | D48: =VLOOKUP(C48,Regnskap,3,FALSE) -> 0
C49: =Regnskap!B55 -> 7300 Markedsføring og representasjon | D49: =VLOOKUP(C49,Regnskap,3,FALSE) -> 0
...
